Workbook
Name Receptlist: Recept!$A:$A
Name Receptlista: Tabell4[#All]
Name Recepttabell: Tabell4[#All]

Sheet Planering
A1: Vecka | B1: Dag | C1: Måltid
A2: 1 | B2: Måndag | C2: Lunch | D2: Pastasallad med kryddkorv
A3: 1 | B3: Måndag | C3: Lunch | D3: Middag från söndag
A4: 1 | B4: Måndag | C4: Middag | D4: Köttfärssås med linser, bönor & morot + spaghetti
A5: 1 | B5: Tisdag | C5: Lunch | D5: Köttfärssås med linser, bönor & morot + spaghetti
A6: 1 | B6: Tisdag | C6: Middag | D6: Lasagne med linser, bönor & morot
A7: 1 | B7: Onsdag | C7: Lunch | D7: Potatissallad med pulled pork
A8: 1 | B8: Onsdag | C8: Lunch | D8: Lasagne med linser, bönor & morot
A9: 1 | B9: Onsdag | C9: Middag | D9: Palak paneer + ris
A10: 1 | B10: Torsdag | C10: Lunch | D10: Potatissallad med pulled pork
A11: 1 | B11: Torsdag | C11: Lunch | D11: Palak paneer + ris
A12: 1 | B12: Torsdag | C12: Middag | D12: Gräddstuvad pyttipanna med rödbetor & ägg
A13: 1 | B13: Fredag | C13: Lunch | D13: Omelett
A14: 1 | B14: Fredag | C14: Middag
A15: 1 | B15: Lördag | C15: Lunch
A16: 1 | B16: Lördag | C16: Middag
A17: 1 | B17: Söndag | C17: Lunch
A18: 1 | B18: Söndag | C18: Middag
A20: 2 | B20: Måndag | C20: Lunch | D20: Pastasallad med kryddkorv
A21: 2 | B21: Måndag | C21: Lunch
A22: 2 | B22: Måndag | C22: Middag
A23: 2 | B23: Tisdag | C23: Lunch
A24: 2 | B24: Tisdag | C24: Middag
A25: 2 | B25: Onsdag | C25: Lunch | D25: Pastasallad med kyckling
A26: 2 | B26: Onsdag | C26: Lunch
A27: 2 | B27: Onsdag | C27: Middag
A28: 2 | B28: Torsdag | C28: Lunch | D28: Pastasallad med kyckling
A29: 2 | B29: Torsdag | C29: Lunch
A30: 2 | B30: Torsdag | C30: Middag
A31: 2 | B31: Fredag | C31: Lunch
A32: 2 | B32: Fredag | C32: Middag
A33: 2 | B33: Lördag | C33: Lunch
A34: 2 | B34: Lördag | C34: Middag
A35: 2 | B35: Söndag | C35: Lunch
A36: 2 | B36: Söndag | C36: Middag
A38: 3 | B38: Måndag | C38: Lunch | D38: Pastasallad med kryddkorv
A39: 3 | B39: Måndag | C39: Lunch
A40: 3 | B40: Måndag | C40: Middag
A41: 3 | B41: Tisdag | C41: Lunch
A42: 3 | B42: Tisdag | C42: Middag
...

Sheet Recept
A1: Recept | B1: Beskrivning | C1: Portioner
A2: Pastasallad med kryddkorv | B2: Kall pastasallad med kryddkorv, småtomater, lök, ärtor & aioli. | C2: 2
A3: Potatissallad med pulled pork | B3: Kall potatissallad med pulled pork, lök, bönor & aioli. | C3: 2
A4: Pastasallad med kyckling | B4: Kall pastasallad med kyckling, bacon, majs, lök & currymajonnäs. | C4: 2
A6: Köttfärssås med linser, bönor & morot + spaghetti | B6: Köttfärssås med extra linser, bönor & riven morot, serveras med spaghetti. | C6: 4
A7: Lasagne med linser, bönor & morot | B7: Lasagne med köttfärs, linser, bönor & morot i tomatsås och béchamel. | C7: 8
A9: Korv stroganoff + ris | B9: Klassisk korv stroganoff med ris. | C9: 4
A10: Kryddig korv med stuvade makaroner | B10: Stekt kryddkorv med krämigt stuvade makaroner. | C10: 2
A11: Kycklingpasta med curry & ärtor | B11: Krämig kycklingpasta med curry, lök & ärtor. | C11: 4
A12: Pasta med kyckling, bacon, grädde & paprika | B12: Krämig pasta med kyckling, bacon, paprika & lök. | C12: 4
A14: Palak paneer + ris | B14: Indisk spenatgryta med paneer/grillost, serveras med ris. | C14: 4
A15: Linsgryta + ris | B15: Kryddig linsgryta med tomat & grönsaker, serveras med ris. | C15: 4
A16: Ugnsomelett med potatis & grönsaker | B16: Omelett i ugn med potatis, ost & grönsaker. | C16: 2
... A35: Omelett | B35: Snabb omelett i stekpanna, bra “släng i vad som finns”-rätt. | C35: 2

Sheet Ingredienser
A1: Recept | B1: Ingrediens | C1: Mängd | D1: Enhet
A2: Pastasallad med kryddkorv | B2: Pasta | C2: 150 | D2: g
A3: Pastasallad med kryddkorv | B3: Kryddkorv | C3: 3 | D3: st
A4: Pastasallad med kryddkorv | B4: Småtomater | C4: 100 | D4: g
A5: Pastasallad med kryddkorv | B5: Lök (gul/salladslök/purjo) | C5: 1 | D5: st
A6: Pastasallad med kryddkorv | B6: Frysta ärtor | C6: 50 | D6: g
A7: Pastasallad med kryddkorv | B7: Rapsolja | C7: 2 | D7: dl
A8: Pastasallad med kryddkorv | B8: Ägg | C8: 1 | D8: st
A9: Pastasallad med kryddkorv | B9: Vitlök | C9: 1 | D9: klyfta
A10: Pastasallad med kryddkorv | B10: Vitvinsvinäger | C10: 1 | D10: msk
A11: Pastasallad med kryddkorv | B11: Senap | C11: 1 | D11: msk
A13: Potatissallad med pulled pork | B13: Potatis | C13: 200 | D13: g
A14: Potatissallad med pulled pork | B14: Pulled pork | C14: 100 | D14: g
... A31: Pastasallad med kyckling | B31: Senap | C31: 1 | D31: msk
A32: Pastasallad med kyckling | B32: Curry
A34: Köttfärssås med linser, bönor & morot + spaghetti | B34: Nöt- eller blandfärs | C34: 400 | D34: g
A35: Köttfärssås med linser, bönor & morot + spaghetti | B35: Matlagningsgrädde | C35: 1.5 | D35: dl
A36: Köttfärssås med linser, bönor & morot + spaghetti | B36: Bönor | C36: 1 | D36: burk
A37: Köttfärssås med linser, bönor & morot + spaghetti | B37: Morot | C37: 2 | D37: st
A38: Köttfärssås med linser, bönor & morot + spaghetti | B38: Gul lök | C38: 1 | D38: st
A39: Köttfärssås med linser, bönor & morot + spaghetti | B39: Krossade tomater | C39: 1 | D39: burk
A40: Köttfärssås med linser, bönor & morot + spaghetti | B40: Spaghetti | C40: 300 | D40: g
A41: Köttfärssås med linser, bönor & morot + spaghetti | B41: Tomatpuré | C41: 3 | D41: msk
A43: Lasagne med linser, bönor & morot | B43: Nöt- eller blandfärs | C43: 400 | D43: g
A44: Lasagne med linser, bönor & morot | B44: Röda linser | C44: 1 | D44: burk
A45: Lasagne med linser, bönor & morot | B45: Bönor | C45: 1 | D45: burk
A46: Lasagne med linser, bönor & morot | B46: Morot | C46: 2 | D46: st
... A65: Kryddig korv med stuvade makaroner | B65: Mjölk | C65: 3 | D65: dl
A66: Kryddig korv med stuvade makaroner | B66: Vetemjöl | C66: 0.3 | D66: dl
A68: Kycklingpasta med curry & ärtor | B68: Kyckling | C68: 300 | D68: g
A69: Kycklingpasta med curry & ärtor | B69: Pasta | C69: 250 | D69: g
A70: Kycklingpasta med curry & ärtor | B70: Frysta ärtor | C70: 100 | D70: g
A71: Kycklingpasta med curry & ärtor | B71: Gul lök | C71: 1 | D71: st
A72: Kycklingpasta med curry & ärtor | B72: Matlagningsgrädde | C72: 2 | D72: dl
A73: Kycklingpasta med curry & ärtor | B73: Curry | C73: 5 | D73: g
A75: Pasta med kyckling, bacon, grädde & paprika | B75: Kyckling | C75: 250 | D75: g
A76: Pasta med kyckling, bacon, grädde & paprika | B76: Bacon | C76: 1 | D76: pkt
A77: Pasta med kyckling, bacon, grädde & paprika | B77: Paprika | C77: 1 | D77: st
A78: Pasta med kyckling, bacon, grädde & paprika | B78: Gul lök | C78: 1 | D78: st
A79: Pasta med kyckling, bacon, grädde & paprika | B79: Matlagningsgrädde | C79: 2 | D79: dl
...

Sheet Inköpslista
A1: Ingrediens | B1: Total mängd | C1: Enhet | E1: Planerade recept | G1: Vecka att handla för | H1: Recept vald vecka
A2: {=_xlfn.UNIQUE(_xlfn._xlws.FILTER(Ingredienser!B:B,ISERROR(MATCH(Ingredienser!A:A,_xlfn.ANCHORARRAY($H$2),0))=FALSE))} -> Pasta | B2: {=SUM(_xlfn._xlws.FILTER(Ingredienser!C:C,(Ingredienser!B:B=A2)*(ISERROR(MATCH(Ingredienser!A:A,_xlfn.ANCHORARRAY($H$2),0))=FALSE)))} -> 150 | C2: =_xlfn.XLOOKUP(A2,Ingredienser!B:B,Ingredienser!D:D,"") -> g | E2: {=_xlfn.UNIQUE(_xlfn._xlws.FILTER(Planering!D:D,Planering!D:D<>""))} -> Pastasallad med kryddkorv | G2: 1 | H2: {=_xlfn.UNIQUE(_xlfn._xlws.FILTER(Planering!D:D,Planering!A:A=$G$2))} -> Pastasallad med kryddkorv
A3: Kryddkorv | B3: =IF(A3="","",SUMIF(Ingredienser!B:B,A3,Ingredienser!C:C)) -> 3 | C3: =IF(A3="","",_xlfn.XLOOKUP(A3,Ingredienser!B:B,Ingredienser!D:D,"")) -> st | E3: Middag från söndag | H3: Middag från söndag
A4: Småtomater | B4: =IF(A4="","",SUMIF(Ingredienser!B:B,A4,Ingredienser!C:C)) -> 100 | C4: =IF(A4="","",_xlfn.XLOOKUP(A4,Ingredienser!B:B,Ingredienser!D:D,"")) -> g | E4: Köttfärssås med linser, bönor & morot + spaghetti | H4: Köttfärssås med linser, bönor & morot + spaghetti
A5: Lök (gul/salladslök/purjo) | B5: =IF(A5="","",SUMIF(Ingredienser!B:B,A5,Ingredienser!C:C)) -> 3 | C5: =IF(A5="","",_xlfn.XLOOKUP(A5,Ingredienser!B:B,Ingredienser!D:D,"")) -> st | E5: Lasagne med linser, bönor & morot | H5: Lasagne med linser, bönor & morot
A6: Frysta ärtor | B6: =IF(A6="","",SUMIF(Ingredienser!B:B,A6,Ingredienser!C:C)) -> 350 | C6: =IF(A6="","",_xlfn.XLOOKUP(A6,Ingredienser!B:B,Ingredienser!D:D,"")) -> g | E6: Potatissallad med pulled pork | H6: Potatissallad med pulled pork
A7: Rapsolja | B7: =IF(A7="","",SUMIF(Ingredienser!B:B,A7,Ingredienser!C:C)) -> 6 | C7: =IF(A7="","",_xlfn.XLOOKUP(A7,Ingredienser!B:B,Ingredienser!D:D,"")) -> dl | E7: Palak paneer + ris | H7: Palak paneer + ris
A8: Ägg | B8: =IF(A8="","",SUMIF(Ingredienser!B:B,A8,Ingredienser!C:C)) -> 21 | C8: =IF(A8="","",_xlfn.XLOOKUP(A8,Ingredienser!B:B,Ingredienser!D:D,"")) -> st | E8: Gräddstuvad pyttipanna med rödbetor & ägg | H8: Gräddstuvad pyttipanna med rödbetor & ägg
A9: Vitlök | B9: =IF(A9="","",SUMIF(Ingredienser!B:B,A9,Ingredienser!C:C)) -> 3 | C9: =IF(A9="","",_xlfn.XLOOKUP(A9,Ingredienser!B:B,Ingredienser!D:D,"")) -> klyfta | E9: Omelett | H9: Omelett
A10: Vitvinsvinäger | B10: =IF(A10="","",SUMIF(Ingredienser!B:B,A10,Ingredienser!C:C)) -> 3 | C10: =IF(A10="","",_xlfn.XLOOKUP(A10,Ingredienser!B:B,Ingredienser!D:D,"")) -> msk | E10: Pastasallad med kyckling | H10: 0
A11: Senap | B11: =IF(A11="","",SUMIF(Ingredienser!B:B,A11,Ingredienser!C:C)) -> 3 | C11: =IF(A11="","",_xlfn.XLOOKUP(A11,Ingredienser!B:B,Ingredienser!D:D,"")) -> msk
A12: 0 | B12: =IF(A12="","",SUMIF(Ingredienser!B:B,A12,Ingredienser!C:C)) -> 0 | C12: =IF(A12="","",_xlfn.XLOOKUP(A12,Ingredienser!B:B,Ingredienser!D:D,""))
A13: Potatis | B13: =IF(A13="","",SUMIF(Ingredienser!B:B,A13,Ingredienser!C:C)) -> 1616 | C13: =IF(A13="","",_xlfn.XLOOKUP(A13,Ingredienser!B:B,Ingredienser!D:D,"")) -> g
A14: Pulled pork | B14: =IF(A14="","",SUMIF(Ingredienser!B:B,A14,Ingredienser!C:C)) -> 100 | C14: =IF(A14="","",_xlfn.XLOOKUP(A14,Ingredienser!B:B,Ingredienser!D:D,"")) -> g
A15: Bönor | B15: =IF(A15="","",SUMIF(Ingredienser!B:B,A15,Ingredienser!C:C)) -> 3 | C15: =IF(A15="","",_xlfn.XLOOKUP(A15,Ingredienser!B:B,Ingredienser!D:D,"")) -> burk
A16: Nöt- eller blandfärs | B16: =IF(A16="","",SUMIF(Ingredienser!B:B,A16,Ingredienser!C:C)) -> 1400 | C16: =IF(A16="","",_xlfn.XLOOKUP(A16,Ingredienser!B:B,Ingredienser!D:D,"")) -> g
A17: Matlagningsgrädde | B17: =IF(A17="","",SUMIF(Ingredienser!B:B,A17,Ingredienser!C:C)) -> 312.5 | C17: =IF(A17="","",_xlfn.XLOOKUP(A17,Ingredienser!B:B,Ingredienser!D:D,"")) -> dl
A18: Morot | B18: =IF(A18="","",SUMIF(Ingredienser!B:B,A18,Ingredienser!C:C)) -> 84 | C18: =IF(A18="","",_xlfn.XLOOKUP(A18,Ingredienser!B:B,Ingredienser!D:D,"")) -> st
A19: Gul lök | B19: =IF(A19="","",SUMIF(Ingredienser!B:B,A19,Ingredienser!C:C)) -> 13 | C19: =IF(A19="","",_xlfn.XLOOKUP(A19,Ingredienser!B:B,Ingredienser!D:D,"")) -> st
A20: Krossade tomater | B20: =IF(A20="","",SUMIF(Ingredienser!B:B,A20,Ingredienser!C:C)) -> 504 | C20: =IF(A20="","",_xlfn.XLOOKUP(A20,Ingredienser!B:B,Ingredienser!D:D,"")) -> burk
A21: Spaghetti | B21: =IF(A21="","",SUMIF(Ingredienser!B:B,A21,Ingredienser!C:C)) -> 550 | C21: =IF(A21="","",_xlfn.XLOOKUP(A21,Ingredienser!B:B,Ingredienser!D:D,"")) -> g
A22: Tomatpuré | B22: =IF(A22="","",SUMIF(Ingredienser!B:B,A22,Ingredienser!C:C)) -> 10 | C22: =IF(A22="","",_xlfn.XLOOKUP(A22,Ingredienser!B:B,Ingredienser!D:D,"")) -> msk
A23: Röda linser | B23: =IF(A23="","",SUMIF(Ingredienser!B:B,A23,Ingredienser!C:C)) -> 161 | C23: =IF(A23="","",_xlfn.XLOOKUP(A23,Ingredienser!B:B,Ingredienser!D:D,"")) -> burk
A24: Lasagneplattor | B24: =IF(A24="","",SUMIF(Ingredienser!B:B,A24,Ingredienser!C:C)) -> 200 | C24: =IF(A24="","",_xlfn.XLOOKUP(A24,Ingredienser!B:B,Ingredienser!D:D,"")) -> g
... A35: Smör/olja | B35: =IF(A35="","",SUMIF(Ingredienser!B:B,A35,Ingredienser!C:C)) -> 10 | C35: =IF(A35="","",_xlfn.XLOOKUP(A35,Ingredienser!B:B,Ingredienser!D:D,"")) -> g
B36: =IF(A36="","",SUMIF(Ingredienser!B:B,A36,Ingredienser!C:C)) | C36: =IF(A36="","",_xlfn.XLOOKUP(A36,Ingredienser!B:B,Ingredienser!D:D,""))
B37: =IF(A37="","",SUMIF(Ingredienser!B:B,A37,Ingredienser!C:C)) | C37: =IF(A37="","",_xlfn.XLOOKUP(A37,Ingredienser!B:B,Ingredienser!D:D,""))
B38: =IF(A38="","",SUMIF(Ingredienser!B:B,A38,Ingredienser!C:C)) | C38: =IF(A38="","",_xlfn.XLOOKUP(A38,Ingredienser!B:B,Ingredienser!D:D,""))
B39: =IF(A39="","",SUMIF(Ingredienser!B:B,A39,Ingredienser!C:C)) | C39: =IF(A39="","",_xlfn.XLOOKUP(A39,Ingredienser!B:B,Ingredienser!D:D,""))
B40: =IF(A40="","",SUMIF(Ingredienser!B:B,A40,Ingredienser!C:C)) | C40: =IF(A40="","",_xlfn.XLOOKUP(A40,Ingredienser!B:B,Ingredienser!D:D,""))
B41: =IF(A41="","",SUMIF(Ingredienser!B:B,A41,Ingredienser!C:C)) | C41: =IF(A41="","",_xlfn.XLOOKUP(A41,Ingredienser!B:B,Ingredienser!D:D,""))
B42: =IF(A42="","",SUMIF(Ingredienser!B:B,A42,Ingredienser!C:C)) | C42: =IF(A42="","",_xlfn.XLOOKUP(A42,Ingredienser!B:B,Ingredienser!D:D,""))
B43: =IF(A43="","",SUMIF(Ingredienser!B:B,A43,Ingredienser!C:C)) | C43: =IF(A43="","",_xlfn.XLOOKUP(A43,Ingredienser!B:B,Ingredienser!D:D,""))
B44: =IF(A44="","",SUMIF(Ingredienser!B:B,A44,Ingredienser!C:C)) | C44: =IF(A44="","",_xlfn.XLOOKUP(A44,Ingredienser!B:B,Ingredienser!D:D,""))
B45: =IF(A45="","",SUMIF(Ingredienser!B:B,A45,Ingredienser!C:C)) | C45: =IF(A45="","",_xlfn.XLOOKUP(A45,Ingredienser!B:B,Ingredienser!D:D,""))
B46: =IF(A46="","",SUMIF(Ingredienser!B:B,A46,Ingredienser!C:C)) | C46: =IF(A46="","",_xlfn.XLOOKUP(A46,Ingredienser!B:B,Ingredienser!D:D,""))
B47: =IF(A47="","",SUMIF(Ingredienser!B:B,A47,Ingredienser!C:C)) | C47: =IF(A47="","",_xlfn.XLOOKUP(A47,Ingredienser!B:B,Ingredienser!D:D,""))
... B72: =IF(A72="","",SUMIF(Ingredienser!B:B,A72,Ingredienser!C:C)) | C72: =IF(A72="","",_xlfn.XLOOKUP(A72,Ingredienser!B:B,Ingredienser!D:D,""))
